<?xml version="1.0"?>
<robot xmlns:xacro="http://www.ros.org/wiki/xacro">

  <xacro:macro name="two_dof" params="parent prefix *origin">

  <!-- Constants for robot dimensions -->
  <xacro:property name="mass" value="1" />
  <xacro:property name="width" value="0.1" />
  <xacro:property name="height1" value="2" />
  <xacro:property name="height2" value="1" />
  <xacro:property name="height3" value="1" />
  <xacro:property name="axel_offset" value="0.00" />

  <joint name="${prefix}base_joint" type="fixed">
    <xacro:insert_block name="origin" />
    <parent link="${parent}"/>
    <child link="${prefix}base_link" />
  </joint>

  <!-- Base Link -->
  <link name="${prefix}base_link">
      <visual>
        <origin xyz="0 0 0" rpy="0 0 0"/>
        <geometry>
          <mesh filename="package://synapticon_ros2_control/meshes/flywheel.stl" scale="0.005 0.005 0.005"/>
        </geometry>
      </visual>
      <collision>
        <origin xyz="0 0 0" rpy="0 0 0"/>
        <geometry>
          <mesh filename="package://synapticon_ros2_control/meshes/flywheel.stl" scale="0.005 0.005 0.005"/>
        </geometry>
      </collision>
   </link>

  <joint name="${prefix}joint1" type="continuous">
    <parent link="${prefix}base_link"/>
    <child link="${prefix}link1"/>
    <origin xyz="0 0 0" rpy="0 0 0"/>
    <axis xyz="0 0 1"/>
    <dynamics damping="0.7"/>
    <limit effort="100" velocity="1.0"/>
  </joint>

  <!-- Middle Link -->
  <link name="${prefix}link1">
      <visual>
        <origin xyz="0 0 0" rpy="0 0 0"/>
        <geometry>
          <mesh filename="package://synapticon_ros2_control/meshes/motor.stl" scale="0.005 0.005 0.005"/>
        </geometry>
      </visual>
      <collision>
        <origin xyz="0 0 0" rpy="0 0 0"/>
        <geometry>
          <mesh filename="package://synapticon_ros2_control/meshes/motor.stl" scale="0.005 0.005 0.005"/>
        </geometry>
      </collision>
    </link>

  <joint name="${prefix}fixed_joint" type="fixed">  <!-- Renamed to avoid duplicate base_joint -->
    <parent link="${prefix}link1"/>
    <child link="${prefix}link2"/>
    <origin xyz="0 1.1 0" rpy="0 0 0"/>
  </joint>

  <!-- Fixed Link -->
  <link name="${prefix}link2">
      <visual>
        <origin xyz="0 0 0" rpy="0 0 0"/>
        <geometry>
          <mesh filename="package://synapticon_ros2_control/meshes/motor.stl" scale="0.005 0.005 0.005"/>
        </geometry>
      </visual>
      <collision>
        <origin xyz="0 0 0" rpy="0 0 0"/>
        <geometry>
          <mesh filename="package://synapticon_ros2_control/meshes/motor.stl" scale="0.005 0.005 0.005"/>
        </geometry>
      </collision>
   </link>

  <joint name="${prefix}joint2" type="continuous">
    <parent link="${prefix}link2"/>
    <child link="${prefix}link3"/>
    <origin xyz="0 0 0" rpy="0 0 0"/>
    <axis xyz="0 0 1"/>
    <dynamics damping="0.7"/>
    <limit effort="100" velocity="1.0"/>
  </joint>

  <!-- Flywheel 2 Link -->
  <link name="${prefix}link3">
      <visual>
        <origin xyz="0 0 0" rpy="0 0 0"/>
        <geometry>
          <mesh filename="package://synapticon_ros2_control/meshes/flywheel.stl" scale="0.005 0.005 0.005"/>
        </geometry>
      </visual>
      <collision>
        <origin xyz="0 0 0" rpy="0 0 0"/>
        <geometry>
          <mesh filename="package://synapticon_ros2_control/meshes/flywheel.stl" scale="0.005 0.005 0.005"/>
        </geometry>
      </collision>
   </link>

  </xacro:macro>

</robot>
